Workbook

Sheet Summary
A1: Bangladeshi news portals — fetchability summary
A2: Counts are formulas over the Sources sheet.
A4: Method | B4: Portals | C4: Bangla | D4: English | E4: What it means
A5: RSS | B5: =COUNTIF(Sources!$F$2:$F$65,A5) -> 16 | C5: =COUNTIFS(Sources!$F$2:$F$65,A5,Sources!$C$2:$C$65,"Bangla") -> 14 | D5: =COUNTIFS(Sources!$F$2:$F$65,A5,Sources!$C$2:$C$65,"English") -> 2 | E5: Feed with title + link. Easiest.
A6: Sitemap | B6: =COUNTIF(Sources!$F$2:$F$65,A6) -> 12 | C6: =COUNTIFS(Sources!$F$2:$F$65,A6,Sources!$C$2:$C$65,"Bangla") -> 10 | D6: =COUNTIFS(Sources!$F$2:$F$65,A6,Sources!$C$2:$C$65,"English") -> 2 | E6: Google News sitemap (news:title + loc). As good as RSS.
A7: HTML | B7: =COUNTIF(Sources!$F$2:$F$65,A7) -> 20 | C7: =COUNTIFS(Sources!$F$2:$F$65,A7,Sources!$C$2:$C$65,"Bangla") -> 13 | D7: =COUNTIFS(Sources!$F$2:$F$65,A7,Sources!$C$2:$C$65,"English") -> 7 | E7: Parse homepage links. Works but can break on redesigns.
A8: Unclear | B8: =COUNTIF(Sources!$F$2:$F$65,A8) -> 5 | C8: =COUNTIFS(Sources!$F$2:$F$65,A8,Sources!$C$2:$C$65,"Bangla") -> 4 | D8: =COUNTIFS(Sources!$F$2:$F$65,A8,Sources!$C$2:$C$65,"English") -> 1 | E8: Stale data, or links without titles.
A9: Unavailable | B9: =COUNTIF(Sources!$F$2:$F$65,A9) -> 11 | C9: =COUNTIFS(Sources!$F$2:$F$65,A9,Sources!$C$2:$C$65,"Bangla") -> 9 | D9: =COUNTIFS(Sources!$F$2:$F$65,A9,Sources!$C$2:$C$65,"English") -> 2 | E9: Blocked (403/402), down, or JS-only.
A10: Total checked | B10: =SUM(B5:B9) -> 64 | C10: =SUM(C5:C9) -> 50 | D10: =SUM(D5:D9) -> 14
A11: Usable now (RSS + Sitemap + HTML) | B11: =B5+B6+B7 -> 48 | C11: =C5+C6+C7 -> 37 | D11: =D5+D6+D7 -> 11
A12: Structured only (RSS + Sitemap) | B12: =B5+B6 -> 28 | C12: =C5+C6 -> 24 | D12: =D5+D6 -> 4

Sheet Sources
A1: # | B1: Portal | C1: Language | D1: Type | E1: Homepage | F1: Method | G1: Fetch URL | H1: Items (approx.) | I1: Article URL pattern (HTML only) | J1: Notes
A2: 1 | B2: Prothom Alo | C2: Bangla | D2: Newspaper | E2: https://www.prothomalo.com | F2: RSS | G2: https://www.prothomalo.com/feed/ | H2: 12 | J2: Live RSS 2.0
A3: 2 | B3: Prothom Alo English | C3: English | D3: Newspaper | E3: https://en.prothomalo.com | F3: RSS | G3: https://en.prothomalo.com/feed/ | H3: 2 | J3: Live but only ~2 items; poll often
A4: 3 | B4: The Daily Star | C4: English | D4: Newspaper | E4: https://www.thedailystar.net | F4: HTML | G4: https://www.thedailystar.net/ | I4: /news/.+-\d{5,}$ | J4: /rss.xml stale (newest 1 Jun 2026); /frontpage/rss.xml stale (2022)
A5: 4 | B5: The Daily Star Bangla | C5: Bangla | D5: Newspaper | E5: https://bangla.thedailystar.net | F5: HTML | G5: https://bangla.thedailystar.net/ | I5: /news-\d{5,}$ | J5: /rss.xml stale (Feb 2026)
A6: 5 | B6: bdnews24 Bangla | C6: Bangla | D6: Online | E6: https://bangla.bdnews24.com | F6: HTML | G6: https://bangla.bdnews24.com/ | I6: ^/[a-z-]+/[a-z0-9]{8,12}$ | J6: Old widget RSS URL now returns homepage HTML
A7: 6 | B7: bdnews24 English | C7: English | D7: Online | E7: https://bdnews24.com | F7: HTML | G7: https://bdnews24.com/ | I7: ^/[a-z-]+/[a-z0-9]{8,12}$ | J7: Old widget RSS URL now returns homepage HTML
A8: 7 | B8: Dhaka Tribune | C8: English | D8: Newspaper | E8: https://www.dhakatribune.com | F8: Sitemap | G8: https://www.dhakatribune.com/news-sitemap.xml | H8: 100+ | J8: Google News sitemap; /feed is 404
A9: 8 | B9: Bangla Tribune | C9: Bangla | D9: Online | E9: https://www.banglatribune.com | F9: Sitemap | G9: https://www.banglatribune.com/news-sitemap.xml | H9: 50 | J9: Google News sitemap; /feed/ is 404
A10: 9 | B10: The Business Standard | C10: English | D10: Newspaper | E10: https://www.tbsnews.net | F10: HTML | G10: https://www.tbsnews.net/ | I10: /[a-z-]+/.+-\d{5,}$ | J10: /rss.xml stale (2021)
A11: 10 | B11: TBS Bangla | C11: Bangla | D11: Newspaper | E11: https://www.tbsnews.net/bangla | F11: HTML | G11: https://www.tbsnews.net/bangla | I11: ^/bangla/.+-\d{5,}$ | J11: /bangla/rss.xml stale (Oct 2025)
A12: 11 | B12: Jugantor | C12: Bangla | D12: Newspaper | E12: https://www.jugantor.com | F12: Sitemap | G12: https://www.jugantor.com/news_sitemap.xml | H12: 100 | J12: Underscore filename; found via /sitemap.xml
A13: 12 | B13: Kaler Kantho | C13: Bangla | D13: Newspaper | E13: https://www.kalerkantho.com | F13: Sitemap | G13: https://www.kalerkantho.com/daily-sitemap/{YYYY-MM-DD}/sitemap.xml | H13: 121 | J13: One sitemap per day (index: /sitemap.xml); ~1 day lag
A14: 13 | B14: Samakal | C14: Bangla | D14: Newspaper | E14: https://samakal.com | F14: Unclear | G14: https://samakal.com/news_sitemap.xml | H14: 51 | J14: Sitemap newest item ~10 days old; homepage and RSS return 403
A15: 14 | B15: Ittefaq | C15: Bangla | D15: Newspaper | E15: https://www.ittefaq.com.bd | F15: Sitemap | G15: https://www.ittefaq.com.bd/news-sitemap.xml | H15: 40 | J15: Google News sitemap
A16: 15 | B16: Bangladesh Pratidin | C16: Bangla | D16: Newspaper | E16: https://www.bd-pratidin.com | F16: Unavailable | J16: 403 on every URL tested
A17: 16 | B17: Naya Diganta | C17: Bangla | D17: Newspaper | E17: https://dailynayadiganta.com | F17: HTML | G17: https://dailynayadiganta.com/ | I17: ^/post/[a-z-]+/\d+ | J17: www host fails SSL; use bare domain
A18: 17 | B18: Manab Zamin | C18: Bangla | D18: Newspaper | E18: https://www.mzamin.com | F18: HTML | G18: https://www.mzamin.com/ | I18: ^/article/\d+ | J18: No RSS (404)
A19: 18 | B19: Desh Rupantor | C19: Bangla | D19: Newspaper | E19: https://www.deshrupantor.com | F19: Sitemap | G19: https://www.deshrupantor.com/news-sitemap.xml | H19: 50 | J19: Google News sitemap
A20: 19 | B20: Kalbela | C20: Bangla | D20: Newspaper | E20: https://www.kalbela.com | F20: HTML | G20: https://www.kalbela.com/ | I20: ^/[a-z-]+(/[a-z-]+)?/\d{4,}$ | J20: RSS paths empty / 403
A21: 20 | B21: Ajker Patrika | C21: Bangla | D21: Newspaper | E21: https://www.ajkerpatrika.com | F21: RSS | G21: https://www.ajkerpatrika.com/feed | H21: 20 | J21: Live RSS 2.0
A22: 21 | B22: Bonik Barta | C22: Bangla | D22: Newspaper | E22: https://bonikbarta.com | F22: Unclear | G22: https://bonikbarta.com/sitemaps/sitemap-news-{YYYY-MM-DD}.xml | H22: 60 | J22: Daily sitemap has links but no titles; homepage JS-rendered
A23: 22 | B23: Janakantha | C23: Bangla | D23: Newspaper | E23: https://www.dailyjanakantha.com | F23: Unavailable | J23: XML returns 403; homepage stale, no links
A24: 23 | B24: Inqilab | C24: Bangla | D24: Newspaper | E24: https://dailyinqilab.com | F24: Unavailable | J24: 403; www host shows stale 2020 content
A25: 24 | B25: Bhorer Kagoj | C25: Bangla | D25: Newspaper | E25: https://www.bhorerkagoj.net | F25: HTML | G25: https://www.bhorerkagoj.net/ | I25: ^/[a-z-]+/\d{5,} | J25: bhorerkagoj.com redirects to .net
A26: 25 | B26: Amader Shomoy | C26: Bangla | D26: Newspaper | E26: https://www.dainikamadershomoy.com | F26: Unavailable | J26: No feed/sitemap; homepage JS-rendered
A27: 26 | B27: Sangbad | C27: Bangla | D27: Newspaper | E27: https://sangbad.net | F27: RSS | G27: https://sangbad.net/rss.xml | H27: 8 | J27: sangbad.net.bd redirects here; small feed
A28: 27 | B28: Jago News 24 | C28: Bangla | D28: Online | E28: https://www.jagonews24.com | F28: HTML | G28: https://www.jagonews24.com/ | I28: /news/\d+ | J28: /rss/rss.xml is a soft 404
A29: 28 | B29: Dhaka Post | C29: Bangla | D29: Online | E29: https://www.dhakapost.com | F29: RSS | G29: https://www.dhakapost.com/rss/rss.xml | H29: 20 | J29: Live RSS 2.0
A30: 29 | B30: Rising BD | C30: Bangla | D30: Online | E30: https://www.risingbd.com | F30: RSS | G30: https://www.risingbd.com/rss/rss.xml | H30: 50 | J30: Live RSS 2.0
A31: 30 | B31: Banglanews24 | C31: Bangla | D31: Online | E31: https://www.banglanews24.com | F31: Unavailable | J31: HTTP 402 on everything (bot blocking)
A32: 31 | B32: Daily Bangladesh | C32: Bangla | D32: Online | E32: https://www.daily-bangladesh.com | F32: RSS | G32: https://www.daily-bangladesh.com/rss.xml | H32: 10 | J32: /rss/rss.xml is 404
A33: 32 | B33: Sarabangla | C33: Bangla | D33: Online | E33: https://sarabangla.net | F33: RSS | G33: https://sarabangla.net/feed/ | H33: 10 | J33: Live RSS 2.0
A34: 33 | B34: Barta24 | C34: Bangla | D34: Online | E34: https://barta24.com | F34: RSS | G34: https://barta24.com/rss/rss.xml | H34: 50 | J34: Contains duplicates; dedupe by link
A35: 34 | B35: Dhaka Times 24 | C35: Bangla | D35: Online | E35: https://www.dhakatimes24.com | F35: HTML | G35: https://www.dhakatimes24.com/ | I35: ^/\d{4}/\d{2}/\d{2}/\d+ | J35: RSS paths return homepage (soft 404)
A36: 35 | B36: Bangla Insider | C36: Bangla | D36: Online | E36: https://www.banglainsider.com | F36: Unavailable | J36: robots.txt disallows automated fetchers
A37: 36 | B37: Ekushey TV | C37: Bangla | D37: TV | E37: https://www.ekushey-tv.com | F37: RSS | G37: https://www.ekushey-tv.com/rss/rss.xml | H37: 30 | J37: Live RSS 2.0
A38: 37 | B38: Somoy News | C38: Bangla | D38: TV | E38: https://www.somoynews.tv | F38: Unavailable | J38: Site under maintenance (live stream only)
A39: 38 | B39: Jamuna TV | C39: Bangla | D39: TV | E39: https://www.jamuna.tv | F39: Sitemap | G39: https://www.jamuna.tv/news_sitemap.xml | H39: ~200 | J39: Homepage 403; sitemap works
A40: 39 | B40: Channel i Online | C40: Bangla | D40: TV | E40: https://www.channelionline.com | F40: RSS | G40: https://www.channelionline.com/feed/ | H40: 30 | J40: WordPress RSS
...
